Workbook

Sheet Graphs and Tables
A1: Mark Recapture 2025
N5: Snakeden 2025 | Q5: Glade 2025
N6: Initial Release | O6: 1578 | Q6: Initial Release | R6: 1224
N7: Pass 1 | O7: ='Where Found Snakeden'!K8 -> 74 | Q7: Pass 1 | R7: ='Where Found Glade'!K9 -> 297
N8: Pass 2 | O8: ='Where Found Snakeden'!L8 -> 68 | Q8: Pass 2 | R8: ='Where Found Glade'!L9 -> 293
N9: Pass 3 | O9: ='Where Found Snakeden'!M8 -> 74 | Q9: Pass 3 | R9: ='Where Found Glade'!M9 -> 234
N10: Pass 4 | O10: ='Where Found Snakeden'!N8 -> 62 | Q10: Pass 4 | R10: ='Where Found Glade'!N9 -> 266
N11: =[1]Summary!K6 -> Total Observations: | O11: ='Where Found Snakeden'!K27 -> 278 | Q11: Total Observations: | R11: ='Where Found Glade'!K30 -> 1090
N12: Total Tagged Mussels Found: | O12: ='Where Found Snakeden'!K26 -> 213 | Q12: Total Tagged Mussels Found: | R12: ='Where Found Glade'!K29 -> 665
N13: Found in Multiple Passes: | O13: ='Where Found Snakeden'!K28 -> 25 | Q13: Found in Multiple Passes: | R13: ='Where Found Glade'!K31 -> 281
N14: =[1]Summary!K8 -> Found outside of MR: | O14: 0 | Q14: Found outside of MR: | R14: 0
N15: Total Found Dead | O15: ='Where Found Snakeden'!#REF! -> #REF! | Q15: Total Found Dead | R15: ='Where Found Glade'!K37 -> 83
N16: Total Found Alive | O16: ='Where Found Snakeden'!#REF! -> #REF! | Q16: Total Found Alive | R16: ='Where Found Glade'!K36 -> 1007
N17: Unknown (Tagged but tag not recorded and found Alive (included in Alive)) | O17: 11 | Q17: Unknown (Tagged but tag not recorded and found Alive (included in Alive)) | R17: =SUM('Where Found Glade'!K6:N6) -> 3
N18: Unknown (Tagged but tag not recorded and found Dead (included in Dead)) | O18: 1 | Q18: Unknown (Tagged but tag not recorded and found Dead (included in Dead)) | R18: 0
N19: Untagged and dead (included in Dead) | O19: =SUM('Where Found Snakeden'!K7:N7) -> 24 | Q19: Untagged and dead (included in Dead) | R19: =SUM('Where Found Glade'!K7:N7) -> 2
N20: ='Where Found Snakeden'!J29 -> Tagged Mussels Found only Once | O20: ='Where Found Snakeden'!K29 -> 188 | Q20: ='Where Found Glade'!J32 -> Tagged Mussels Found only Once | R20: ='Where Found Glade'!K32 -> 384
N21: ='Where Found Snakeden'!J30 -> Tagged Mussels Found Twice | O21: ='Where Found Snakeden'!K30 -> 22 | Q21: ='Where Found Glade'!J33 -> Tagged Mussels Found Twice | R21: ='Where Found Glade'!K33 -> 177
N22: ='Where Found Snakeden'!J31 -> Tagged Mussels Found Thrice | O22: ='Where Found Snakeden'!K31 -> 3 | Q22: ='Where Found Glade'!J34 -> Tagged Mussels Found Thrice | R22: ='Where Found Glade'!K34 -> 77
N23: ='Where Found Snakeden'!J32 -> Tagged Mussels Found 4 times | O23: ='Where Found Snakeden'!K32 -> 0 | Q23: ='Where Found Glade'!J35 -> Tagged Mussels Found 4 times | R23: ='Where Found Glade'!K35 -> 27
Q26: =[1]Summary!W18 -> Glade Initial Released | R26: 1224
Q27: =[1]Summary!W19 -> Snakeden Initial Released | R27: 1578
Q28: =[1]Summary!W20 -> Initial Released | R28: =[1]Summary!X20 -> 2802
N30: Snakeden | Q30: Glade
N31: =[1]Summary!K23 -> Alive: | Q31: =[1]Summary!W22 -> Alive:
N32: =[1]Summary!K24 -> Pass 1 | O32: ='Snakeden MR'!E79 -> 30 | Q32: =[1]Summary!W23 -> Pass 1 | R32: ='Glade MR'!E303 -> 264
N33: =[1]Summary!K25 -> Pass 2 | O33: ='Snakeden MR'!L73 -> 27 | Q33: =[1]Summary!W24 -> Pass 2 | R33: ='Glade MR'!L303 -> 271
N34: =[1]Summary!K26 -> Pass 3 | O34: ='Snakeden MR'!S79 -> 34 | Q34: =[1]Summary!W25 -> Pass 3 | R34: ='Glade MR'!S240 -> 214
N35: =[1]Summary!K27 -> Pass 4 | O35: ='Snakeden MR'!Z67 -> 43 | Q35: =[1]Summary!W26 -> Pass 4 | R35: ='Glade MR'!Z273 -> 258
N36: =[1]Summary!K28 -> Dead: | Q36: =[1]Summary!W27 -> Dead:
N37: =[1]Summary!K29 -> Pass 1 | O37: ='Snakeden MR'!E80 -> 44 | Q37: =[1]Summary!W28 -> Pass 1 | R37: ='Glade MR'!E304 -> 33
N38: =[1]Summary!K30 -> Pass 2 | O38: ='Snakeden MR'!L74 -> 41 | Q38: =[1]Summary!W29 -> Pass 2 | R38: ='Glade MR'!L304 -> 22
N39: =[1]Summary!K31 -> Pass 3 | O39: ='Snakeden MR'!S80 -> 40 | Q39: =[1]Summary!W30 -> Pass 3 | R39: ='Glade MR'!S241 -> 20
N40: =[1]Summary!K32 -> Pass 4 | O40: ='Snakeden MR'!Z68 -> 19 | Q40: =[1]Summary!W31 -> Pass 4 | R40: ='Glade MR'!Z274 -> 8
N41: =[1]Summary!K33 -> % Found Alive | Q41: =[1]Summary!W32 -> % Found Alive
N42: =[1]Summary!K34 -> Pass 1 | O42: =(O32/O7) -> 0.40540541 | Q42: =[1]Summary!W33 -> Pass 1 | R42: =(R32/R7) -> 0.88888889
N43: =[1]Summary!K35 -> Pass 2 | O43: =(O33/O8) -> 0.39705882 | Q43: =[1]Summary!W34 -> Pass 2 | R43: =(R33/R8) -> 0.92491468
N44: =[1]Summary!K36 -> Pass 3 | O44: =(O34/O9) -> 0.45945946 | Q44: =[1]Summary!W35 -> Pass 3 | R44: =(R34/R9) -> 0.91452991
N45: =[1]Summary!K37 -> Pass 4 | O45: =(O35/O10) -> 0.69354839 | Q45: =[1]Summary!W36 -> Pass 4 | R45: =(R35/R10) -> 0.96992481
N46: =[1]Summary!K38 -> % Found in each pass | Q46: =[1]Summary!W37 -> % Found in each pass
...

Sheet Snakeden MR
A1: Mark Recapture 2025 | B1: Mark and Recapture #1 (7/17/2025) | I1: Mark and Recapture #2 (8/29/2025) | P1: Mark and Recapture #3 (9/19/2025) | W1: Mark and Recapture #4 (9/30/2025-10/1/2025)
B2: Site Notes: | C2: Person Hours: (2 * 1:10) + ( 2*3:15) Water Temp: 28.0C Crew: Athan Anderson, Parker Sullivan, Maddie Carver, Lily Warco | I2: Site Notes: | J2: Time Spent Searching: 0:30 (thursday), 4:30 (Friday) Water Temp: 24.8C Crew: Athan Anderson, Eleanor Stauch, Jasmine Treynor-Hawke | P2: Site Notes: | Q2: Time Spent Searching: 4 hours Water Temp: 19.1C Crew: Athan Anderson, Ellie Stauch Notes: Leaf Litter Beginnning | W2: Site Notes: | X2: Time Spent Searching: 5 hours Water Temp: Crew: Athan Anderson, Jess Jones | AD2: Site Notes: | AK2: Site Notes: | AR2: Site Notes:
B3: Location Found | C3: Tag Number | D3: Length (mm) | E3: Status | F3: Where Found | G3: Notes | I3: Location Found | J3: Tag Number | K3: Length (mm) | L3: Status | M3: Where Found | N3: Notes | O3: for MR 3: | P3: Location Found | Q3: Tag Number | R3: Length (mm) | S3: Status | T3: Where Found | U3: Notes | W3: Location Found | X3: Tag Number | Y3: Length (mm) | Z3: Status | AA3: Where Found | AB3: Notes | AD3: Location Found | AE3: Tag Number | AF3: Length (mm) | AG3: Status | AH3: Where Found | AI3: Notes | AK3: Location Found | AL3: Tag Number | AM3: Length (mm) | AN3: Status | AO3: Where Found | AP3: Notes | AR3: Location Found | AS3: Tag Number | AT3: Length (mm) | AU3: Status | AV3: Where Found | AW3: Notes
B4: GS Pool | C4: O058 | D4: 92.5 | E4: Alive | F4: pool | G4: New Tag | I4: Pool F | J4: O165 | K4: 83.7 | L4: Alive | N4: New Tag | O4: counted 17 pools going down -> upstream Athan's data --------------> | P4: Pool F | Q4: D260 | R4: - | S4: Dead | V4: Correct nomenclature (pool 8 is uppermost pool, pool 9 is SOND) | W4: Pool A | X4: Unknown | Y4: - | Z4: Alive
B5: GS Pool | C5: b744 | D5: - | E5: Dead | I5: Pool C | J5: B805 | K5: - | L5: Dead | O5: counted 19 pools going up -> downstream | P5: Pool B | Q5: D626 | R5: 74.2 | S5: Alive | U5: real = 74.2 | W5: Pool B | X5: untagged | Y5: - | Z5: Dead
B6: GS Pool | C6: c091 | D6: - | E6: Dead | I6: Pool B | J6: D621 | K6: 74.3 | L6: Alive | O6: idk what happened | P6: Pool B | Q6: B364 | R6: 84.5 | S6: Alive | W6: Pool B | X6: Unknown | Z6: Alive | AB6: PIT
B7: GS Pool | C7: c224 | D7: 86.7 | E7: Alive | I7: Pool B | J7: D804 | K7: 71.5 | L7: Alive | O7: data entered to the best of my ability -_- | P7: Pool B | Q7: C794 | R7: - | S7: Dead | W7: Pool C | X7: B226 | Y7: 66.3 | Z7: Alive
B8: GS Pool | C8: d778 | D8: 82.7 | E8: Alive | I8: Pool B | J8: C673 | K8: - | L8: Dead | O8: Pool 1 is uppermost pool | P8: GS Pool | Q8: B652 | R8: =O14*90.7+0.2 -> 89.651314 | S8: Alive | U8: 90 = 46.3 (?) | W8: Pool D | X8: Unknown | Z8: Alive
B9: GS Pool | C9: c196 | D9: - | E9: Dead | I9: Pool B | J9: B884 | K9: - | L9: Dead | P9: GS Pool | Q9: B243 | R9: =O14*75+0.2 -> 74.167459 | S9: Alive | U9: 70 = 67.2 | W9: Trib | X9: B405 | Z9: Dead
B10: GS Pool | C10: b348 | D10: - | E10: Dead | I10: Pool 1 | J10: untagged | K10: - | L10: Dead | O10: I need to do calculations for my data I think | P10: Pool 2 | Q10: B293 | R10: - | S10: Dead | W10: Pool E | X10: Unknown | Z10: Alive
B11: GS Pool | C11: c121 | D11: - | E11: Dead | I11: Pool 1 | J11: D786 | K11: - | L11: Dead | P11: Pool 2 | Q11: B959 | R11: 87.284355 | S11: Alive | U11: 90 = 86.2 | W11: Pool F | X11: Unknown | Z11: Alive
B12: GS Pool | C12: b278 | D12: 87.3 | E12: Alive | I12: Pool 1 | J12: D863 | K12: - | L12: Dead | O12: 0=0.2, 80=79.1 | P12: Pool 2 | Q12: C284 | R12: 77.816521 | S12: Alive | U12: 80 = 78.2 | W12: Riffle (F -> E) | X12: O087 | Y12: 92 | Z12: Alive
B13: GS Pool | C13: C414 | D13: 84.7 | E13: Alive | I13: Pool 1 | J13: C573 | K13: - | L13: Dead | P13: Pool 2 | Q13: untagged | R13: - | S13: Dead | W13: Pool G | X13: Untagged | Z13: Dead
B14: GS Pool | C14: B540 | D14: 77.9 | E14: Alive | I14: Pool 1 | J14: C110 | K14: - | L14: Dead | O14: =(79.1-0.3)/(80-0.1) -> 0.98623279 | P14: Riffle B | Q14: O089 | R14: 78.605507 | S14: Alive | U14: 80 = 78.3 new tag | W14: Pool G | X14: D767 | Y14: 64 | Z14: Alive
B15: GS Pool | C15: D333 | D15: - | E15: Dead | I15: Pool 1 | J15: B261 | K15: 91.3 | L15: Alive | O15: Athan Pool 15 = SOND downstream | P15: Riffle B | Q15: C788 | R15: 62.628536 | S15: Alive | U15: 60 = 58.1 | W15: Pool G | X15: D241 | Y15: 77.2 | Z15: Dead
B16: Pool A | C16: C399 | D16: - | E16: Dead | I16: Pool 2 | J16: B948 | K16: 96 | L16: Alive | P16: Riffle B | Q16: C143 | R16: 90.144431 | S16: Alive | U16: 90 = 87.4 | W16: Pool G | X16: D108 | Y16: 70.8 | Z16: Alive
B17: Pool A | C17: C627 | D17: - | E17: Dead | I17: Pool 2 | J17: B403 | K17: 80.5 | L17: Alive | P17: Riffle B | Q17: C488 | R17: 75.350939 | S17: Alive | U17: 70 = 68.3 | W17: Pool G | X17: D582 | Z17: Dead
B18: Pool A | C18: b281 | D18: - | E18: Dead | I18: Pool 2 | J18: C002 | K18: 67.4 | L18: Alive | P18: Riffle B | Q18: B505 | R18: - | S18: Dead | W18: Pool G | X18: Unknown | Z18: Dead | AB18: too deep to get to
B19: Pool A | C19: b573 | D19: - | E19: Dead | I19: Pool 2 | J19: C529 | K19: 80.9 | L19: Alive | P19: Riffle B | Q19: D186 | R19: 65.291364 | S19: Alive | U19: 60 = 58.3 | W19: Pool G | X19: Unknown | Z19: Alive | AB19: too deep to get to
B20: Pool A | C20: D573 | D20: 64.7 | E20: Alive | I20: Pool 2 | J20: C320 | K20: 93.7 | L20: Alive | P20: Riffle B | Q20: C011 | R20: 75.055069 | S20: Alive | U20: 70 = 68.3(?) | W20: Pool G | X20: Unknown | Z20: Alive | AB20: too deep to get to
B21: Pool A | C21: C842 | D21: 66.7 | E21: Alive | I21: Pool 2 | J21: B305 | K21: - | L21: Dead | P21: Riffle B | Q21: B285 | R21: - | S21: Alive | U21: 90 = 87.3 | W21: Pool H | X21: Unknown | Z21: Alive
B22: Pool A | C22: B523 | D22: - | E22: Dead | I22: Pool 2 | J22: untagged | K22: - | L22: Dead | P22: Riffle B | Q22: B613 | R22: 83.043554 | S22: Alive | U22: 80 = 78.4 | W22: Riffle (H -> I) | X22: Unknown | Z22: Alive
B23: Pool A | C23: B246 | D23: - | E23: Dead | I23: Pool 2 | J23: D146 | K23: - | L23: Dead | P23: Riffle B | Q23: B123 | R23: - | S23: Dead | W23: Pool I | X23: Unknown | Z23: Alive
B24: Pool A | C24: D047 | D24: - | E24: Dead | G24: bank | I24: Pool 2 | J24: B218 | K24: - | L24: Dead | P24: Pool 3 | Q24: C250 | R24: 57.007009 | S24: Alive | U24: 50 = 48.3 | W24: GS Pool | X24: C201 | Z24: Dead
B25: Pool A | C25: D805 | D25: - | E25: Dead | I25: Pool 3 | J25: B543 | K25: 71 | L25: Alive | P25: Pool 4 | Q25: C179 | R25: - | S25: Dead | W25: GS Pool | X25: C626 | Y25: 68 | Z25: Alive
B26: Pool A | C26: B275 | D26: - | E26: Dead | I26: Pool 3 | J26: D684 | K26: - | L26: Dead | P26: Pool 4 | Q26: B320 | R26: - | S26: Dead | W26: GS Pool | X26: D618 | Y26: 65.5 | Z26: Alive
B27: Pool B | C27: C673 | D27: 76.1 | E27: Alive | F27: pool | I27: Pool 3 | J27: D697 | K27: - | L27: Dead | P27: Pool 4 | Q27: untagged | R27: - | S27: Dead | W27: GS Pool | X27: C669 | Y27: 51 | Z27: Alive
B28: Pool B | C28: D614 | D28: - | E28: Dead | I28: Riffle 1 | J28: B843 | K28: - | L28: Dead | P28: Pool 5 | Q28: B967 | R28: - | S28: Dead | W28: GS Pool | X28: B278 | Y28: 84 | Z28: Alive
B29: Pool B | C29: B364 | D29: 86.5 | E29: Alive | I29: Riffle 1 | J29: O069 | K29: 93.4 | L29: Alive | N29: New Tag | P29: Pool 5 | Q29: Untagged | R29: - | S29: Dead | U29: fragment | W29: GS Pool | X29: B243 | Y29: 77 | Z29: Alive
B30: Pool C | C30: D637 | D30: - | E30: Dead | I30: Riffle 1 | J30: B684 | K30: 90.4 | L30: Alive | P30: Pool 5 | Q30: D196 | R30: 82.846308 | S30: Alive | U30: 80 = 78.3 | W30: GS Pool | X30: B365 | Y30: 83 | Z30: Alive
B31: Pool D | C31: B226 | D31: 66.6 | E31: Alive | F31: pool | I31: Riffle 1 | J31: B766 | K31: 85 | L31: Alive | P31: Pool 5 | Q31: D742 | R31: 80.183479 | S31: Alive | U31: 80 = 78.2 | W31: GS Pool | X31: B483 | Y31: 81 | Z31: Alive
B32: Pool F | C32: C315 | D32: - | E32: Dead | I32: Riffle 2 | J32: untagged | K32: - | L32: Dead | N32: fragment | P32: Riffle 3 | Q32: B803 | R32: - | S32: Dead | W32: GS Pool | X32: C370 | Y32: 84.2 | Z32: Alive
B33: Pool F | C33: C666 | D33: - | E33: Dead | I33: Riffle 2 | J33: untagged | K33: - | L33: Dead | P33: Pool 6 | Q33: C116 | R33: 92.018273 | S33: Alive | U33: 90 = 87.4 | W33: GS Pool | X33: C320 | Y33: 93.8 | Z33: Alive
B34: Pool 5 | C34: B236 | D34: 69.5 | E34: Alive | I34: Riffle 2 | J34: B525 | K34: - | L34: Dead | N34: fragment | P34: Pool 6 | Q34: C028 | R34: - | S34: Dead | W34: GS Pool | X34: C552 | Y34: 87.7 | Z34: Alive
B35: Pool 5 | C35: B995 | D35: - | E35: Dead | I35: Riffle 2 | J35: D292 | K35: - | L35: Dead | P35: Pool 6 | Q35: untagged | R35: - | S35: Dead | U35: fragment | W35: GS Pool | X35: C387 | Y35: 102 | Z35: Alive
B36: Pool 5 | C36: D664 | D36: 61 | E36: Alive | I36: Pool 4 | J36: D181 | K36: 65 | L36: Alive | P36: Pool 6 | Q36: B471 | R36: 89.749937 | S36: Alive | U36: 90 = 87.5 | W36: GS Pool | X36: O088 | Y36: 87.5 | Z36: Alive
B37: Pool 5 | C37: C327 | D37: 85.2 | E37: Alive | I37: Pool 4 | J37: B518 | K37: 81.7 | L37: Alive | P37: Pool 6 | Q37: B553 | R37: - | S37: Dead | W37: GS Pool | X37: B652 | Y37: 93.5 | Z37: Alive
B38: Pool 5 | C38: C899 | D38: 56.4 | E38: Alive | H38: Athan's data | I38: Riffle 2 | J38: C576 | K38: - | L38: Dead | P38: Pool 6 | Q38: D298 | R38: - | S38: Dead | W38: GS Pool | X38: C277 | Y38: 91.3 | Z38: Alive
B39: Pool 5 | C39: C538 | D39: 92.8 | E39: Alive | I39: Riffle 2 | J39: D393 | K39: - | L39: Dead | P39: Pool 6 | Q39: B488 | R39: - | S39: Dead | W39: GS Pool | X39: O101 | Y39: 78.5 | Z39: Alive | AB39: new tag
B40: Pool 4 | C40: c127 | D40: 83 | E40: Alive | I40: Pool 4 | J40: C327 | K40: 85 | L40: Alive | P40: Pool 8 | Q40: O090 | R40: 81.761452 | S40: Alive | U40: 80 = 78.4 new tag | W40: Pool 1 | X40: B564 | Z40: Dead | AB40: First P above GS
...

Sheet Glade MR
A1: * Note: After the final MR for 2025, the pools were reordered based on dissapearances from the drought. The new order is 9 pools instead of 11. Refer to this map: https://docs.google.com/presentation/d/1_T00HroF_DTlcdYvavOO_hGOJ51vfcswc2lztCjAkGU/edit?slide=id.p#slide=id.p
A2: Mark Recapture 2025 | B2: Mark and Recapture #1 (7/18/2025) | I2: Mark and Recapture #2 (8/29/2025) | P2: Mark and Recapture #3 (9/18-19/25) | W2: Mark and Recapture #4 (9/29-30/2025) | AK2: Mussels found by Brennan (9/26/2024)
B3: Site Notes: | C3: Person Hours: (4*2) + (4*4?) Water Temp: 27.0C Crew: Athan Anderson, Parker Sullivan, Maddie Carver, Lily Warco | I3: Site Notes: | J3: Time Spent Searching: 0:30 (thursday), 4:30 (Friday) Water Temp: 24.8C (recorded as 21.6C on Ellie's slate) Crew: Athan Anderson, Eleanor Stauch, Jasmine Traynor-Hawke | P3: Site Notes: | Q3: Time Spent Searching: Water Temp: 18.1C Crew: Athan Anderson, Ellie Stauch | W3: Site Notes: | X3: Time Spent Searching: Water Temp: Crew: Athan Anderson, Jess Jones | AD3: Site Notes: | AK3: Site Notes:
B4: Location Found | C4: Tag Number | D4: Length (mm) | E4: Status | F4: Where Found | G4: Notes | I4: Location Found | J4: Tag Number | K4: Length (mm) | L4: Status | M4: Where Found | N4: Notes | P4: Location Found | Q4: Tag Number | R4: Length (mm) | S4: Status | T4: Where Found | U4: Notes | W4: Location Found | X4: Tag Number | Y4: Length (mm) | Z4: Status | AA4: Where Found | AB4: Notes | AD4: Location Found | AE4: Tag Number | AF4: Length (mm) | AG4: Status | AH4: Where Found | AI4: Notes | AK4: Location Found | AL4: Tag Number | AM4: Length (mm) | AN4: Status | AO4: Where Found | AP4: Notes
B5: Pool 11 | C5: C841 | D5: - | E5: dead | H5: Ellie's data | I5: 50 m -> gauge station | J5: D382 | K5: 86.2 | L5: alive | M5: pool | P5: 50 m -> GS | Q5: B662 | R5: 91.5 | S5: alive | W5: 50 m below GS | X5: D382 | Y5: 87 | Z5: alive
B6: Pool 11 | C6: C820 | D6: - | E6: dead | I6: 50 m -> gauge station | J6: B605 | K6: 87.4 | L6: alive | M6: pool | P6: 50 m -> GS | Q6: O084 | R6: 92.9 | S6: alive | U6: new tag | W6: 50 m below GS | X6: B662 | Y6: 91.1 | Z6: alive
B7: Pool 11 | C7: C907 | D7: - | E7: dead | I7: 50 m -> gauge station | J7: D346 | K7: 79.1 | L7: alive | M7: riffle | P7: 50 m -> GS | Q7: D506 | R7: 92.9 | S7: alive | W7: 50 m below GS | X7: O084 | Y7: 92.8 | Z7: alive
B8: Pool 11 | C8: C996 | D8: - | E8: dead | I8: riffle after GS | J8: D342 | K8: - | L8: dead | P8: 50 m -> GS | Q8: B167 | R8: 73.4 | S8: alive | W8: 50 m below GS | X8: B605 | Y8: 88.4 | Z8: alive
B9: Pool 11 | C9: C400 | D9: - | E9: dead | I9: Pool 11 | J9: D927 | K9: - | L9: dead | P9: GS pool | Q9: D032 | R9: 60.5 | S9: alive | W9: GS Pool | X9: D032 | Y9: 60.8 | Z9: alive
B10: Pool 11 | C10: C879 | D10: - | E10: dead | I10: Pool 11 | J10: C252 | K10: - | L10: dead | P10: Pool 11 | Q10: C988 | R10: 66.4 | S10: alive | W10: Pool 11 | X10: D818 | Y10: 86.8 | Z10: alive
B11: Pool 11 | C11: C154 | D11: - | E11: dead | I11: Pool 11 | J11: C763 | K11: - | L11: dead | P11: Pool 11 | Q11: C721 | R11: 74.4 | S11: alive | W11: Pool 11 | X11: C679 | Y11: 65.7 | Z11: alive
B12: Pool 11 | C12: C336 | D12: 91.1 | E12: alive | I12: Pool 11 | J12: B987 | K12: 75 | L12: alive | P12: Pool 11 | Q12: C719 | R12: 76.2 | S12: alive | W12: Pool 11 | X12: C696 | Y12: 63.1 | Z12: alive
B13: Pool 11 | C13: C681 | D13: 70.3 | E13: alive | I13: Pool 11 | J13: C719 | K13: 74 | L13: alive | P13: Pool 11 | Q13: C975 | R13: 58.4 | S13: alive | W13: Pool 11 | X13: B921 | Y13: 83 | Z13: alive
B14: Pool 11 | C14: D508 | D14: 94 | E14: alive | I14: Pool 11 | J14: C573 | K14: 84.4 | L14: alive | P14: Pool 11 | Q14: D815 | R14: 85.7 | S14: alive | W14: Pool 11 | X14: D330 | Y14: 80.5 | Z14: alive
B15: Pool 11 | C15: C573 | D15: 85.5 | E15: alive | I15: Pool 11 | J15: C984 | K15: 61.9 | L15: alive | P15: Pool 11 | Q15: B987 | R15: 75.4 | S15: alive | W15: Pool 11 | X15: D508 | Y15: 95.4 | Z15: alive
B16: Pool 11 | C16: C108 | D16: 65 | E16: alive | I16: Pool 11 | J16: C298 | K16: 78.2 | L16: alive | P16: Pool 11 | Q16: D516 | R16: 69.1 | S16: alive | W16: Pool 11 | X16: C750 | Y16: - | Z16: dead
B17: Pool 11 | C17: C972 | D17: 65 | E17: alive | I17: Pool 10 | J17: B669 | K17: 84.2 | L17: alive | P17: Pool 11 | Q17: C946 | R17: 69.5 | S17: alive | W17: Pool 11 | X17: C719 | Y17: 75.1 (76.1?) | Z17: alive
B18: Pool 11 | C18: C698 | D18: - | E18: dead | I18: Pool 10 | J18: D413 | K18: 102.7 | L18: alive | P18: Pool 11 | Q18: C286 | R18: 96.7 | S18: alive | W18: Pool 11 | X18: D495 | Y18: 92.2 | Z18: alive
B19: Pool 11 | C19: C252 | D19: 69 | E19: alive | I19: Pool 10 | J19: C955 | K19: 74 | L19: alive | P19: Pool 11 | Q19: C545 | R19: 82 | S19: alive | W19: Pool 11 | X19: C294 | Y19: 86.9 | Z19: alive
B20: Pool 11 | C20: B993 | D20: 71 | E20: alive | I20: Pool 10 | J20: C271 | K20: 85 | L20: alive | P20: Pool 11 | Q20: D565 | R20: 70.2 | S20: alive | W20: Pool 11 | X20: C721 | Y20: 74.5 | Z20: alive
B21: Pool 11 | C21: C171 | D21: 87.4 | E21: alive | I21: Pool 10 | J21: D551 | K21: 66.7 | L21: alive | P21: Pool 11 | Q21: C472 | R21: 85.6 | S21: alive | W21: Pool 11 | X21: C680 | Y21: - | Z21: dead
B22: Pool 11 | C22: C984 | D22: 61 | E22: alive | I22: Pool 10 | J22: C296 | K22: 85 | L22: alive | P22: Pool 11 | Q22: D330 | R22: 80.5 | S22: alive | W22: Pool 11 | X22: B987 | Y22: 75.4 | Z22: alive
B23: Pool 11 | C23: C298 | D23: 78.1 | E23: alive | I23: Pool 10 | J23: D362 | K23: 80.3 | L23: alive | P23: Pool 11 | Q23: C616 | R23: 63 | S23: alive | W23: Pool 11 | X23: C343 | Y23: 90.1 | Z23: alive
B24: Pool 11 | C24: C417 | D24: 91.9 | E24: alive | I24: Pool 9 | J24: B865 | K24: 65.6 | L24: alive | P24: Pool 11 | Q24: C707 | R24: 64.7 | S24: alive | W24: Pool 11 | X24: C079 | Y24: 82.4 | Z24: alive
B25: Pool 11 | C25: B987 | D25: 75 | E25: alive | I25: Pool 8 | J25: C760 | K25: - | L25: dead | P25: Pool 11 | Q25: C336 | R25: 91.7 | S25: alive | W25: Pool 11 | X25: C518 | Y25: 93.5 | Z25: alive
B26: Pool 11 | C26: C286 | D26: 96.5 | E26: alive | I26: Pool 8 | J26: C870 | K26: - | L26: dead | P26: Pool 11 | Q26: C681 | R26: 70.4 | S26: alive | W26: Pool 11 | X26: D819 | Y26: 83.7 | Z26: alive
B27: Pool 11 | C27: Unknown | D27: 63.1 | E27: alive | I27: Pool 8 | J27: C287 | K27: 96 | L27: alive | P27: Pool 11 | Q27: C298 | R27: 78.8 | S27: alive | W27: Pool 11 | X27: B911 | Y27: 67 | Z27: alive
B28: Pool 11 | C28: C061 | D28: 63.5 | E28: alive | I28: Pool 8 | J28: B680 | K28: 98.4 | L28: alive | P28: Pool 11 | Q28: O085 | R28: 89.2 | S28: alive | U28: new tag | W28: Pool 11 | X28: C681 | Y28: 70 | Z28: alive
B29: Pool 11 | C29: D565 | D29: 70.1 | E29: alive | I29: Pool 8 | J29: D483 | K29: 84.1 | L29: alive | P29: Pool 11 | Q29: C417 | R29: 91.7 | S29: alive | W29: Pool 11 | X29: C946 | Y29: 69.6 | Z29: alive
B30: Pool 11 | C30: C518 | D30: 63.1 | E30: alive | I30: Pool 8 | J30: C156 | K30: 86.4 | L30: alive | P30: Pool 11 | Q30: C671 | R30: 66.2 | S30: alive | W30: Pool 11 | X30: D474 | Y30: 86 | Z30: alive
B31: Pool 11 | C31: D516 | D31: 68.5 | E31: alive | I31: Pool 8 | J31: B785 | K31: 84.6 | L31: alive | P31: Pool 11 | Q31: D495 | R31: 92.5 | S31: alive | W31: Pool 11 | X31: C707 | Y31: 64.6 | Z31: alive
B32: Pool 11 | C32: C744 | D32: - | E32: dead | I32: Pool 8 | J32: C438 | K32: 91.1 | L32: alive | P32: Pool 10 | Q32: C423 | R32: 73.9 | S32: alive | W32: Pool 11 | X32: D025 | Y32: 69.1 | Z32: alive
B33: Pool 11 | C33: C052 | D33: 95.3 | E33: alive | I33: Pool 7 | J33: B857 | K33: 103 | L33: alive | P33: Pool 10 | Q33: C422 | R33: 91.4 | S33: alive | W33: Pool 11 | X33: C061 | Y33: 93.7 | Z33: alive
B34: Pool 11 | C34: O049 | D34: 70.6 | E34: alive | I34: Pool 7 | J34: C167 | K34: 74.6 | L34: alive | P34: Pool 10 | Q34: C943 | R34: 67.8 | S34: alive | W34: Pool 11 | X34: C472 | Y34: 85.7 | Z34: alive
B35: Pool 11 | C35: D025 | D35: 68.9 | E35: alive | I35: Pool 5 | J35: C329 | K35: 88.7 | L35: alive | P35: Pool 10 | Q35: B126 | R35: 77.4 | S35: alive | U35: B or D?? | W35: Pool 11 | X35: C545 | Y35: 82.2 | Z35: alive
B36: pool 10 | C36: B174 | D36: 82.8 | E36: alive | I36: Pool 5 | J36: B133 | K36: 83.6 | L36: alive | P36: Pool 10 | Q36: D023 | R36: 57.9 | S36: alive | W36: Pool 11 | X36: C972 | Y36: - | Z36: dead
B37: pool 10 | C37: C955 | D37: 74.5 | E37: alive | I37: Pool 5 | J37: D374 | K37: 80 | L37: alive | P37: Pool 10 | Q37: D413 | R37: 103.2 | S37: alive | W37: Pool 11 | X37: C125 | Y37: 94 | Z37: alive
B38: pool 10 | C38: C271 | D38: 85.9 | E38: alive | I38: Pool 5 | J38: B013 | K38: 93 | L38: alive | P38: Pool 10 | Q38: D469 | R38: 76.4 | S38: alive | W38: Pool 11 | X38: D498 | Y38: 91.5 | Z38: alive
B39: pool 10 | C39: C360 | D39: 86.2 | E39: alive | I39: Pool 5 | J39: B416 | K39: 77.2 | L39: alive | P39: Pool 10 | Q39: B103 | R39: 110.3 | S39: alive | W39: Pool 11 | X39: C717 | Y39: 67.9 | Z39: alive
B40: pool 10 | C40: D413 | D40: 102.7 | E40: alive | I40: Pool 5 | J40: C775 | K40: 72.3 | L40: alive | P40: Pool 10 | Q40: C687 | R40: 67 | S40: alive | W40: Pool 11 | X40: C286 | Y40: 96.9 | Z40: alive
...

Sheet Where Found Snakeden
A1: Mark Recapture 2025
A2: Snakeden
A3: Tag # (red) | B3: Site Added To | C3: Found in pass 1 | D3: Found in pass 2 | E3: Found in pass 3 | F3: Found in pass 4 | G3: Sum Value | H3: Alive or Dead? | I3: Sacrificed? | J3: Totals: | R3: Found in multiple passes
A4: B000 | B4: Glade | C4: =IF(COUNTIF(Table1[Tag Number], A4), 1, 0) -> 0 | D4: =IF(COUNTIF(Table2[Tag Number], A4), 1, 0) -> 0 | E4: =IF(COUNTIF(Table3[Tag Number], A4), 1, 0) -> 0 | F4: =IF(COUNTIF(Table4[Tag Number], A4), 1, 0) -> 0 | G4: =SUM(C4:F4) -> 0 | H4: {=_xlfn.IFS(OR(_xlfn.XLOOKUP(A4,Table1[Tag Number],Table1[Status],"-",0)="Dead", _xlfn.XLOOKUP(A4,Table2[Tag Number],Table2[Status],"-",0)="Dead", _xlfn.XLOOKUP(A4,Table3[Tag Number],Table3[Status],"-",0)="Dead", _xlfn.XLOOKUP(A4,Table4[Tag Number],Table4[Status],"-",0)="Dead"),"Dead", OR(_xlfn.XLOOKUP(A4,Table1[Tag Number],Table1[Status],"-",0)="Alive", _xlfn.XLOOKUP(A4,Table2[Tag Number],Table2[Status],"-",0)="Alive", _xlfn.XLOOKUP(A4,Table3[Tag Number],Table3[Status],"-",0)="Alive", _xlfn.XLOOKUP(A4,Table4[Tag Number],Table4[Status],"-",0)="Alive"),"Alive", OR(_xlfn.XLOOKUP(A4,Table1[Tag Number],Table1[Status],"-",0)="-", _xlfn.XLOOKUP(A4,Table2[Tag Number],Table2[Status],"-",0)="-", _xlfn.XLOOKUP(A4,Table3[Tag Number],Table3[Status],"-",0)="-", _xlfn.XLOOKUP(A4,Table4[Tag Number],Table4[Status],"-",0)="-"), "-")} -> - | K4: Pass 1 | L4: Pass 2 | M4: Pass 3 | N4: Pass 4 | R4: =IF(G4>1,A4) -> FALSE
A5: B001 | B5: Glade | C5: =IF(COUNTIF(Table1[Tag Number], A5), 1, 0) -> 0 | D5: =IF(COUNTIF(Table2[Tag Number], A5), 1, 0) -> 0 | E5: =IF(COUNTIF(Table3[Tag Number], A5), 1, 0) -> 0 | F5: =IF(COUNTIF(Table4[Tag Number], A5), 1, 0) -> 0 | G5: =SUM(C5:F5) -> 0 | H5: {=_xlfn.IFS(OR(_xlfn.XLOOKUP(A5,Table1[Tag Number],Table1[Status],"-",0)="Dead", _xlfn.XLOOKUP(A5,Table2[Tag Number],Table2[Status],"-",0)="Dead", _xlfn.XLOOKUP(A5,Table3[Tag Number],Table3[Status],"-",0)="Dead", _xlfn.XLOOKUP(A5,Table4[Tag Number],Table4[Status],"-",0)="Dead"),"Dead", OR(_xlfn.XLOOKUP(A5,Table1[Tag Number],Table1[Status],"-",0)="Alive", _xlfn.XLOOKUP(A5,Table2[Tag Number],Table2[Status],"-",0)="Alive", _xlfn.XLOOKUP(A5,Table3[Tag Number],Table3[Status],"-",0)="Alive", _xlfn.XLOOKUP(A5,Table4[Tag Number],Table4[Status],"-",0)="Alive"),"Alive", OR(_xlfn.XLOOKUP(A5,Table1[Tag Number],Table1[Status],"-",0)="-", _xlfn.XLOOKUP(A5,Table2[Tag Number],Table2[Status],"-",0)="-", _xlfn.XLOOKUP(A5,Table3[Tag Number],Table3[Status],"-",0)="-", _xlfn.XLOOKUP(A5,Table4[Tag Number],Table4[Status],"-",0)="-"), "-")} -> - | J5: Tagged | K5: =SUM(C4:C3000) -> 73 | L5: ='Snakeden MR'!I79 -> 58 | M5: =SUM(E4:E3000) -> 63 | N5: =SUM(F4:F3000) -> 48 | R5: =IF(G5>1,A5) -> FALSE
A6: B002 | B6: Glade | C6: =IF(COUNTIF(Table1[Tag Number], A6), 1, 0) -> 0 | D6: =IF(COUNTIF(Table2[Tag Number], A6), 1, 0) -> 0 | E6: =IF(COUNTIF(Table3[Tag Number], A6), 1, 0) -> 0 | F6: =IF(COUNTIF(Table4[Tag Number], A6), 1, 0) -> 0 | G6: =SUM(C6:F6) -> 0 | H6: {=_xlfn.IFS(OR(_xlfn.XLOOKUP(A6,Table1[Tag Number],Table1[Status],"-",0)="Dead", _xlfn.XLOOKUP(A6,Table2[Tag Number],Table2[Status],"-",0)="Dead", _xlfn.XLOOKUP(A6,Table3[Tag Number],Table3[Status],"-",0)="Dead", _xlfn.XLOOKUP(A6,Table4[Tag Number],Table4[Status],"-",0)="Dead"),"Dead", OR(_xlfn.XLOOKUP(A6,Table1[Tag Number],Table1[Status],"-",0)="Alive", _xlfn.XLOOKUP(A6,Table2[Tag Number],Table2[Status],"-",0)="Alive", _xlfn.XLOOKUP(A6,Table3[Tag Number],Table3[Status],"-",0)="Alive", _xlfn.XLOOKUP(A6,Table4[Tag Number],Table4[Status],"-",0)="Alive"),"Alive", OR(_xlfn.XLOOKUP(A6,Table1[Tag Number],Table1[Status],"-",0)="-", _xlfn.XLOOKUP(A6,Table2[Tag Number],Table2[Status],"-",0)="-", _xlfn.XLOOKUP(A6,Table3[Tag Number],Table3[Status],"-",0)="-", _xlfn.XLOOKUP(A6,Table4[Tag Number],Table4[Status],"-",0)="-"), "-")} -> - | J6: Unknown | K6: {=MAX(SUM(COUNTIF(Table1[Tag Number],{"*Unknown*","*-*","*shell*"})),K8-(K7+K5))} -> 0 | L6: {=MAX(SUM(COUNTIF(Table2[Tag Number],{"*Unknown*","*-*","*shell*"})),L8-(L5+L7))} -> 0 | M6: {=MAX(SUM(COUNTIF(Table3[Tag Number],{"*Unknown*","*-*","*shell*"})),M8-(M5+M7))} -> 1 | N6: {=MAX(SUM(COUNTIF(Table4[Tag Number],{"*Unknown*","*-*","*shell*"})),N8-(N7+N5))} -> 11 | R6: =IF(G6>1,A6) -> FALSE
A7: B003 | B7: Glade | C7: =IF(COUNTIF(Table1[Tag Number], A7), 1, 0) -> 0 | D7: =IF(COUNTIF(Table2[Tag Number], A7), 1, 0) -> 0 | E7: =IF(COUNTIF(Table3[Tag Number], A7), 1, 0) -> 0 | F7: =IF(COUNTIF(Table4[Tag Number], A7), 1, 0) -> 0 | G7: =SUM(C7:F7) -> 0 | H7: {=_xlfn.IFS(OR(_xlfn.XLOOKUP(A7,Table1[Tag Number],Table1[Status],"-",0)="Dead", _xlfn.XLOOKUP(A7,Table2[Tag Number],Table2[Status],"-",0)="Dead", _xlfn.XLOOKUP(A7,Table3[Tag Number],Table3[Status],"-",0)="Dead", _xlfn.XLOOKUP(A7,Table4[Tag Number],Table4[Status],"-",0)="Dead"),"Dead", OR(_xlfn.XLOOKUP(A7,Table1[Tag Number],Table1[Status],"-",0)="Alive", _xlfn.XLOOKUP(A7,Table2[Tag Number],Table2[Status],"-",0)="Alive", _xlfn.XLOOKUP(A7,Table3[Tag Number],Table3[Status],"-",0)="Alive", _xlfn.XLOOKUP(A7,Table4[Tag Number],Table4[Status],"-",0)="Alive"),"Alive", OR(_xlfn.XLOOKUP(A7,Table1[Tag Number],Table1[Status],"-",0)="-", _xlfn.XLOOKUP(A7,Table2[Tag Number],Table2[Status],"-",0)="-", _xlfn.XLOOKUP(A7,Table3[Tag Number],Table3[Status],"-",0)="-", _xlfn.XLOOKUP(A7,Table4[Tag Number],Table4[Status],"-",0)="-"), "-")} -> - | J7: Untagged | K7: {=SUM(COUNTIF(Table1[Tag Number],{"Untagged*","UNO0*","UN O0*","New tag*","UN"}))} -> 1 | L7: {=SUM(COUNTIF(Table2[Tag Number],{"Untagged*","UNO0*","UN O0*","New tag*","UN"}))} -> 10 | M7: {=SUM(COUNTIF(Table3[Tag Number],{"Untagged*","UNO0*","UN O0*","New tag*","UN"}))} -> 10 | N7: {=SUM(COUNTIF(Table4[Tag Number],{"Untagged*","UNO0*","UN O0*","New tag*","UN"}))} -> 3 | R7: =IF(G7>1,A7) -> FALSE
A8: B004 | B8: Snakeden | C8: =IF(COUNTIF(Table1[Tag Number], A8), 1, 0) -> 0 | D8: =IF(COUNTIF(Table2[Tag Number], A8), 1, 0) -> 0 | E8: =IF(COUNTIF(Table3[Tag Number], A8), 1, 0) -> 0 | F8: =IF(COUNTIF(Table4[Tag Number], A8), 1, 0) -> 0 | G8: =SUM(C8:F8) -> 0 | H8: {=_xlfn.IFS(OR(_xlfn.XLOOKUP(A8,Table1[Tag Number],Table1[Status],"-",0)="Dead", _xlfn.XLOOKUP(A8,Table2[Tag Number],Table2[Status],"-",0)="Dead", _xlfn.XLOOKUP(A8,Table3[Tag Number],Table3[Status],"-",0)="Dead", _xlfn.XLOOKUP(A8,Table4[Tag Number],Table4[Status],"-",0)="Dead"),"Dead", OR(_xlfn.XLOOKUP(A8,Table1[Tag Number],Table1[Status],"-",0)="Alive", _xlfn.XLOOKUP(A8,Table2[Tag Number],Table2[Status],"-",0)="Alive", _xlfn.XLOOKUP(A8,Table3[Tag Number],Table3[Status],"-",0)="Alive", _xlfn.XLOOKUP(A8,Table4[Tag Number],Table4[Status],"-",0)="Alive"),"Alive", OR(_xlfn.XLOOKUP(A8,Table1[Tag Number],Table1[Status],"-",0)="-", _xlfn.XLOOKUP(A8,Table2[Tag Number],Table2[Status],"-",0)="-", _xlfn.XLOOKUP(A8,Table3[Tag Number],Table3[Status],"-",0)="-", _xlfn.XLOOKUP(A8,Table4[Tag Number],Table4[Status],"-",0)="-"), "-")} -> - | J8: Total | K8: ='Snakeden MR'!B79 -> 74 | L8: ='Snakeden MR'!I73 -> 68 | M8: ='Snakeden MR'!P79 -> 74 | N8: ='Snakeden MR'!W67 -> 62 | R8: =IF(G8>1,A8) -> FALSE
A9: B005 | B9: Glade | C9: =IF(COUNTIF(Table1[Tag Number], A9), 1, 0) -> 0 | D9: =IF(COUNTIF(Table2[Tag Number], A9), 1, 0) -> 0 | E9: =IF(COUNTIF(Table3[Tag Number], A9), 1, 0) -> 0 | F9: =IF(COUNTIF(Table4[Tag Number], A9), 1, 0) -> 0 | G9: =SUM(C9:F9) -> 0 | H9: {=_xlfn.IFS(OR(_xlfn.XLOOKUP(A9,Table1[Tag Number],Table1[Status],"-",0)="Dead", _xlfn.XLOOKUP(A9,Table2[Tag Number],Table2[Status],"-",0)="Dead", _xlfn.XLOOKUP(A9,Table3[Tag Number],Table3[Status],"-",0)="Dead", _xlfn.XLOOKUP(A9,Table4[Tag Number],Table4[Status],"-",0)="Dead"),"Dead", OR(_xlfn.XLOOKUP(A9,Table1[Tag Number],Table1[Status],"-",0)="Alive", _xlfn.XLOOKUP(A9,Table2[Tag Number],Table2[Status],"-",0)="Alive", _xlfn.XLOOKUP(A9,Table3[Tag Number],Table3[Status],"-",0)="Alive", _xlfn.XLOOKUP(A9,Table4[Tag Number],Table4[Status],"-",0)="Alive"),"Alive", OR(_xlfn.XLOOKUP(A9,Table1[Tag Number],Table1[Status],"-",0)="-", _xlfn.XLOOKUP(A9,Table2[Tag Number],Table2[Status],"-",0)="-", _xlfn.XLOOKUP(A9,Table3[Tag Number],Table3[Status],"-",0)="-", _xlfn.XLOOKUP(A9,Table4[Tag Number],Table4[Status],"-",0)="-"), "-")} -> - | R9: =IF(G9>1,A9) -> FALSE
A10: B006 | B10: Glade | C10: =IF(COUNTIF(Table1[Tag Number], A10), 1, 0) -> 0 | D10: =IF(COUNTIF(Table2[Tag Number], A10), 1, 0) -> 0 | E10: =IF(COUNTIF(Table3[Tag Number], A10), 1, 0) -> 0 | F10: =IF(COUNTIF(Table4[Tag Number], A10), 1, 0) -> 0 | G10: =SUM(C10:F10) -> 0 | H10: {=_xlfn.IFS(OR(_xlfn.XLOOKUP(A10,Table1[Tag Number],Table1[Status],"-",0)="Dead", _xlfn.XLOOKUP(A10,Table2[Tag Number],Table2[Status],"-",0)="Dead", _xlfn.XLOOKUP(A10,Table3[Tag Number],Table3[Status],"-",0)="Dead", _xlfn.XLOOKUP(A10,Table4[Tag Number],Table4[Status],"-",0)="Dead"),"Dead", OR(_xlfn.XLOOKUP(A10,Table1[Tag Number],Table1[Status],"-",0)="Alive", _xlfn.XLOOKUP(A10,Table2[Tag Number],Table2[Status],"-",0)="Alive", _xlfn.XLOOKUP(A10,Table3[Tag Number],Table3[Status],"-",0)="Alive", _xlfn.XLOOKUP(A10,Table4[Tag Number],Table4[Status],"-",0)="Alive"),"Alive", OR(_xlfn.XLOOKUP(A10,Table1[Tag Number],Table1[Status],"-",0)="-", _xlfn.XLOOKUP(A10,Table2[Tag Number],Table2[Status],"-",0)="-", _xlfn.XLOOKUP(A10,Table3[Tag Number],Table3[Status],"-",0)="-", _xlfn.XLOOKUP(A10,Table4[Tag Number],Table4[Status],"-",0)="-"), "-")} -> - | K10: Pass 1 | L10: Pass 2 | M10: Pass 3 | N10: Pass 4 | R10: =IF(G10>1,A10) -> FALSE
A11: B007 | B11: Glade | C11: =IF(COUNTIF(Table1[Tag Number], A11), 1, 0) -> 0 | D11: =IF(COUNTIF(Table2[Tag Number], A11), 1, 0) -> 0 | E11: =IF(COUNTIF(Table3[Tag Number], A11), 1, 0) -> 0 | F11: =IF(COUNTIF(Table4[Tag Number], A11), 1, 0) -> 0 | G11: =SUM(C11:F11) -> 0 | H11: {=_xlfn.IFS(OR(_xlfn.XLOOKUP(A11,Table1[Tag Number],Table1[Status],"-",0)="Dead", _xlfn.XLOOKUP(A11,Table2[Tag Number],Table2[Status],"-",0)="Dead", _xlfn.XLOOKUP(A11,Table3[Tag Number],Table3[Status],"-",0)="Dead", _xlfn.XLOOKUP(A11,Table4[Tag Number],Table4[Status],"-",0)="Dead"),"Dead", OR(_xlfn.XLOOKUP(A11,Table1[Tag Number],Table1[Status],"-",0)="Alive", _xlfn.XLOOKUP(A11,Table2[Tag Number],Table2[Status],"-",0)="Alive", _xlfn.XLOOKUP(A11,Table3[Tag Number],Table3[Status],"-",0)="Alive", _xlfn.XLOOKUP(A11,Table4[Tag Number],Table4[Status],"-",0)="Alive"),"Alive", OR(_xlfn.XLOOKUP(A11,Table1[Tag Number],Table1[Status],"-",0)="-", _xlfn.XLOOKUP(A11,Table2[Tag Number],Table2[Status],"-",0)="-", _xlfn.XLOOKUP(A11,Table3[Tag Number],Table3[Status],"-",0)="-", _xlfn.XLOOKUP(A11,Table4[Tag Number],Table4[Status],"-",0)="-"), "-")} -> - | J11: Tagged Alive | K11: {=SUM(COUNTIFS(Table1[Tag Number],{"A*","B*","C*","D*"},Table1[Tag Number],{"<>*-*"},Table1[Status],"Alive"))} -> 27 | L11: {=SUM(COUNTIFS(Table2[Tag Number],{"A*","B*","C*","D*"},Table2[Tag Number],{"<>*-*"},Table2[Status],"Alive"))} -> 25 | M11: {=SUM(COUNTIFS(Table3[Tag Number],{"A*","B*","C*","D*"},Table3[Tag Number],{"<>*-*"},Table3[Status],"Alive"))} -> 30 | N11: {=SUM(COUNTIFS(Table4[Tag Number],{"A*","B*","C*","D*"},Table4[Tag Number],{"<>*-*"},Table4[Status],"Alive"))} -> 30 | R11: =IF(G11>1,A11) -> FALSE
A12: B008 | B12: Glade | C12: =IF(COUNTIF(Table1[Tag Number], A12), 1, 0) -> 0 | D12: =IF(COUNTIF(Table2[Tag Number], A12), 1, 0) -> 0 | E12: =IF(COUNTIF(Table3[Tag Number], A12), 1, 0) -> 0 | F12: =IF(COUNTIF(Table4[Tag Number], A12), 1, 0) -> 0 | G12: =SUM(C12:F12) -> 0 | H12: {=_xlfn.IFS(OR(_xlfn.XLOOKUP(A12,Table1[Tag Number],Table1[Status],"-",0)="Dead", _xlfn.XLOOKUP(A12,Table2[Tag Number],Table2[Status],"-",0)="Dead", _xlfn.XLOOKUP(A12,Table3[Tag Number],Table3[Status],"-",0)="Dead", _xlfn.XLOOKUP(A12,Table4[Tag Number],Table4[Status],"-",0)="Dead"),"Dead", OR(_xlfn.XLOOKUP(A12,Table1[Tag Number],Table1[Status],"-",0)="Alive", _xlfn.XLOOKUP(A12,Table2[Tag Number],Table2[Status],"-",0)="Alive", _xlfn.XLOOKUP(A12,Table3[Tag Number],Table3[Status],"-",0)="Alive", _xlfn.XLOOKUP(A12,Table4[Tag Number],Table4[Status],"-",0)="Alive"),"Alive", OR(_xlfn.XLOOKUP(A12,Table1[Tag Number],Table1[Status],"-",0)="-", _xlfn.XLOOKUP(A12,Table2[Tag Number],Table2[Status],"-",0)="-", _xlfn.XLOOKUP(A12,Table3[Tag Number],Table3[Status],"-",0)="-", _xlfn.XLOOKUP(A12,Table4[Tag Number],Table4[Status],"-",0)="-"), "-")} -> - | J12: Unknown Alive | K12: {=SUM(COUNTIFS(Table1[Tag Number],{"*Unknown*","*-*","*~?*"},Table1[Status],"Alive"))} -> 0 | L12: {=SUM(COUNTIFS(Table2[Tag Number],{"*Unknown*","*-*"},Table2[Status],"Alive"))} -> 0 | M12: {=SUM(COUNTIFS(Table3[Tag Number],{"*Unknown*","*-*"},Table3[Status],"Alive"))} -> 0 | N12: {=SUM(COUNTIFS(Table4[Tag Number],{"*Unknown*","*-*"},Table4[Status],"Alive"))} -> 10 | R12: =IF(G12>1,A12) -> FALSE
A13: B009 | B13: Glade | C13: =IF(COUNTIF(Table1[Tag Number], A13), 1, 0) -> 0 | D13: =IF(COUNTIF(Table2[Tag Number], A13), 1, 0) -> 0 | E13: =IF(COUNTIF(Table3[Tag Number], A13), 1, 0) -> 0 | F13: =IF(COUNTIF(Table4[Tag Number], A13), 1, 0) -> 0 | G13: =SUM(C13:F13) -> 0 | H13: {=_xlfn.IFS(OR(_xlfn.XLOOKUP(A13,Table1[Tag Number],Table1[Status],"-",0)="Dead", _xlfn.XLOOKUP(A13,Table2[Tag Number],Table2[Status],"-",0)="Dead", _xlfn.XLOOKUP(A13,Table3[Tag Number],Table3[Status],"-",0)="Dead", _xlfn.XLOOKUP(A13,Table4[Tag Number],Table4[Status],"-",0)="Dead"),"Dead", OR(_xlfn.XLOOKUP(A13,Table1[Tag Number],Table1[Status],"-",0)="Alive", _xlfn.XLOOKUP(A13,Table2[Tag Number],Table2[Status],"-",0)="Alive", _xlfn.XLOOKUP(A13,Table3[Tag Number],Table3[Status],"-",0)="Alive", _xlfn.XLOOKUP(A13,Table4[Tag Number],Table4[Status],"-",0)="Alive"),"Alive", OR(_xlfn.XLOOKUP(A13,Table1[Tag Number],Table1[Status],"-",0)="-", _xlfn.XLOOKUP(A13,Table2[Tag Number],Table2[Status],"-",0)="-", _xlfn.XLOOKUP(A13,Table3[Tag Number],Table3[Status],"-",0)="-", _xlfn.XLOOKUP(A13,Table4[Tag Number],Table4[Status],"-",0)="-"), "-")} -> - | J13: Untagged Alive | K13: {=SUM(COUNTIFS(Table1[Tag Number],{"Untagged*","*shell*","UN"},Table1[Status],"Alive"))} -> 0 | L13: {=SUM(COUNTIFS(Table2[Tag Number],{"Untagged*","*shell*","UN"},Table2[Status],"Alive"))} -> 0 | M13: {=SUM(COUNTIFS(Table3[Tag Number],{"Untagged*","*shell*","UN"},Table3[Status],"Alive"))} -> 0 | N13: {=SUM(COUNTIFS(Table4[Tag Number],{"Untagged*","*shell*","UN"},Table4[Status],"Alive"))} -> 0 | R13: =IF(G13>1,A13) -> FALSE
A14: B010 | B14: Snakeden | C14: =IF(COUNTIF(Table1[Tag Number], A14), 1, 0) -> 0 | D14: =IF(COUNTIF(Table2[Tag Number], A14), 1, 0) -> 0 | E14: =IF(COUNTIF(Table3[Tag Number], A14), 1, 0) -> 0 | F14: =IF(COUNTIF(Table4[Tag Number], A14), 1, 0) -> 0 | G14: =SUM(C14:F14) -> 0 | H14: {=_xlfn.IFS(OR(_xlfn.XLOOKUP(A14,Table1[Tag Number],Table1[Status],"-",0)="Dead", _xlfn.XLOOKUP(A14,Table2[Tag Number],Table2[Status],"-",0)="Dead", _xlfn.XLOOKUP(A14,Table3[Tag Number],Table3[Status],"-",0)="Dead", _xlfn.XLOOKUP(A14,Table4[Tag Number],Table4[Status],"-",0)="Dead"),"Dead", OR(_xlfn.XLOOKUP(A14,Table1[Tag Number],Table1[Status],"-",0)="Alive", _xlfn.XLOOKUP(A14,Table2[Tag Number],Table2[Status],"-",0)="Alive", _xlfn.XLOOKUP(A14,Table3[Tag Number],Table3[Status],"-",0)="Alive", _xlfn.XLOOKUP(A14,Table4[Tag Number],Table4[Status],"-",0)="Alive"),"Alive", OR(_xlfn.XLOOKUP(A14,Table1[Tag Number],Table1[Status],"-",0)="-", _xlfn.XLOOKUP(A14,Table2[Tag Number],Table2[Status],"-",0)="-", _xlfn.XLOOKUP(A14,Table3[Tag Number],Table3[Status],"-",0)="-", _xlfn.XLOOKUP(A14,Table4[Tag Number],Table4[Status],"-",0)="-"), "-")} -> - | J14: Retagged Alive | K14: {=SUM(COUNTIFS(Table1[Tag Number],{"O*"},Table1[Status],"Alive"))} -> 3 | L14: {=SUM(COUNTIFS(Table2[Tag Number],{"O*"},Table2[Status],"Alive"))} -> 2 | M14: {=SUM(COUNTIFS(Table3[Tag Number],{"O*"},Table3[Status],"Alive"))} -> 4 | N14: {=SUM(COUNTIFS(Table4[Tag Number],{"O*"},Table4[Status],"Alive"))} -> 3 | R14: =IF(G14>1,A14) -> FALSE
A15: B011 | B15: Glade | C15: =IF(COUNTIF(Table1[Tag Number], A15), 1, 0) -> 0 | D15: =IF(COUNTIF(Table2[Tag Number], A15), 1, 0) -> 0 | E15: =IF(COUNTIF(Table3[Tag Number], A15), 1, 0) -> 0 | F15: =IF(COUNTIF(Table4[Tag Number], A15), 1, 0) -> 0 | G15: =SUM(C15:F15) -> 0 | H15: {=_xlfn.IFS(OR(_xlfn.XLOOKUP(A15,Table1[Tag Number],Table1[Status],"-",0)="Dead", _xlfn.XLOOKUP(A15,Table2[Tag Number],Table2[Status],"-",0)="Dead", _xlfn.XLOOKUP(A15,Table3[Tag Number],Table3[Status],"-",0)="Dead", _xlfn.XLOOKUP(A15,Table4[Tag Number],Table4[Status],"-",0)="Dead"),"Dead", OR(_xlfn.XLOOKUP(A15,Table1[Tag Number],Table1[Status],"-",0)="Alive", _xlfn.XLOOKUP(A15,Table2[Tag Number],Table2[Status],"-",0)="Alive", _xlfn.XLOOKUP(A15,Table3[Tag Number],Table3[Status],"-",0)="Alive", _xlfn.XLOOKUP(A15,Table4[Tag Number],Table4[Status],"-",0)="Alive"),"Alive", OR(_xlfn.XLOOKUP(A15,Table1[Tag Number],Table1[Status],"-",0)="-", _xlfn.XLOOKUP(A15,Table2[Tag Number],Table2[Status],"-",0)="-", _xlfn.XLOOKUP(A15,Table3[Tag Number],Table3[Status],"-",0)="-", _xlfn.XLOOKUP(A15,Table4[Tag Number],Table4[Status],"-",0)="-"), "-")} -> - | J15: Tagged Dead | K15: {=SUM(COUNTIFS(Table1[Tag Number],{"A*","B*","C*","D*"},Table1[Tag Number],{"<>*-*"},Table1[Status],"Dead"))} -> 43 | L15: {=SUM(COUNTIFS(Table2[Tag Number],{"A*","B*","C*","D*"},Table2[Tag Number],{"<>*-*"},Table2[Status],"Dead"))} -> 31 | M15: {=SUM(COUNTIFS(Table3[Tag Number],{"A*","B*","C*","D*"},Table3[Tag Number],{"<>*-*"},Table3[Status],"Dead"))} -> 29 | N15: {=SUM(COUNTIFS(Table4[Tag Number],{"A*","B*","C*","D*"},Table4[Tag Number],{"<>*-*"},Table4[Status],"Dead"))} -> 15 | R15: =IF(G15>1,A15) -> FALSE
A16: B012 | B16: Glade | C16: =IF(COUNTIF(Table1[Tag Number], A16), 1, 0) -> 0 | D16: =IF(COUNTIF(Table2[Tag Number], A16), 1, 0) -> 0 | E16: =IF(COUNTIF(Table3[Tag Number], A16), 1, 0) -> 0 | F16: =IF(COUNTIF(Table4[Tag Number], A16), 1, 0) -> 0 | G16: =SUM(C16:F16) -> 0 | H16: {=_xlfn.IFS(OR(_xlfn.XLOOKUP(A16,Table1[Tag Number],Table1[Status],"-",0)="Dead", _xlfn.XLOOKUP(A16,Table2[Tag Number],Table2[Status],"-",0)="Dead", _xlfn.XLOOKUP(A16,Table3[Tag Number],Table3[Status],"-",0)="Dead", _xlfn.XLOOKUP(A16,Table4[Tag Number],Table4[Status],"-",0)="Dead"),"Dead", OR(_xlfn.XLOOKUP(A16,Table1[Tag Number],Table1[Status],"-",0)="Alive", _xlfn.XLOOKUP(A16,Table2[Tag Number],Table2[Status],"-",0)="Alive", _xlfn.XLOOKUP(A16,Table3[Tag Number],Table3[Status],"-",0)="Alive", _xlfn.XLOOKUP(A16,Table4[Tag Number],Table4[Status],"-",0)="Alive"),"Alive", OR(_xlfn.XLOOKUP(A16,Table1[Tag Number],Table1[Status],"-",0)="-", _xlfn.XLOOKUP(A16,Table2[Tag Number],Table2[Status],"-",0)="-", _xlfn.XLOOKUP(A16,Table3[Tag Number],Table3[Status],"-",0)="-", _xlfn.XLOOKUP(A16,Table4[Tag Number],Table4[Status],"-",0)="-"), "-")} -> - | J16: Unknown Dead | K16: {=SUM(COUNTIFS(Table1[Tag Number],{"*Unknown*","*-*","*~?*"},Table1[Status],{"Dead"}))} -> 0 | L16: {=SUM(COUNTIFS(Table2[Tag Number],{"*Unknown*","*-*"},Table2[Status],"Dead"))} -> 0 | M16: {=SUM(COUNTIFS(Table3[Tag Number],{"*Unknown*","*-*"},Table3[Status],"Dead"))} -> 1 | N16: {=SUM(COUNTIFS(Table4[Tag Number],{"*Unknown*","*-*"},Table4[Status],"Dead"))} -> 1 | R16: =IF(G16>1,A16) -> FALSE
A17: B013 | B17: Glade | C17: =IF(COUNTIF(Table1[Tag Number], A17), 1, 0) -> 0 | D17: =IF(COUNTIF(Table2[Tag Number], A17), 1, 0) -> 0 | E17: =IF(COUNTIF(Table3[Tag Number], A17), 1, 0) -> 0 | F17: =IF(COUNTIF(Table4[Tag Number], A17), 1, 0) -> 0 | G17: =SUM(C17:F17) -> 0 | H17: {=_xlfn.IFS(OR(_xlfn.XLOOKUP(A17,Table1[Tag Number],Table1[Status],"-",0)="Dead", _xlfn.XLOOKUP(A17,Table2[Tag Number],Table2[Status],"-",0)="Dead", _xlfn.XLOOKUP(A17,Table3[Tag Number],Table3[Status],"-",0)="Dead", _xlfn.XLOOKUP(A17,Table4[Tag Number],Table4[Status],"-",0)="Dead"),"Dead", OR(_xlfn.XLOOKUP(A17,Table1[Tag Number],Table1[Status],"-",0)="Alive", _xlfn.XLOOKUP(A17,Table2[Tag Number],Table2[Status],"-",0)="Alive", _xlfn.XLOOKUP(A17,Table3[Tag Number],Table3[Status],"-",0)="Alive", _xlfn.XLOOKUP(A17,Table4[Tag Number],Table4[Status],"-",0)="Alive"),"Alive", OR(_xlfn.XLOOKUP(A17,Table1[Tag Number],Table1[Status],"-",0)="-", _xlfn.XLOOKUP(A17,Table2[Tag Number],Table2[Status],"-",0)="-", _xlfn.XLOOKUP(A17,Table3[Tag Number],Table3[Status],"-",0)="-", _xlfn.XLOOKUP(A17,Table4[Tag Number],Table4[Status],"-",0)="-"), "-")} -> - | J17: Untagged Dead | K17: {=SUM(COUNTIFS(Table1[Tag Number],{"Untagged*","*shell*","UN"},Table1[Status],"Dead"))} -> 1 | L17: {=SUM(COUNTIFS(Table2[Tag Number],{"Untagged*","*shell*","UN"},Table2[Status],"Dead"))} -> 10 | M17: {=SUM(COUNTIFS(Table3[Tag Number],{"Untagged*","*shell*","UN"},Table3[Status],"Dead"))} -> 10 | N17: {=SUM(COUNTIFS(Table4[Tag Number],{"Untagged*","*shell*","UN"},Table4[Status],"Dead"))} -> 3 | R17: =IF(G17>1,A17) -> FALSE
A18: B014 | B18: Glade | C18: =IF(COUNTIF(Table1[Tag Number], A18), 1, 0) -> 0 | D18: =IF(COUNTIF(Table2[Tag Number], A18), 1, 0) -> 0 | E18: =IF(COUNTIF(Table3[Tag Number], A18), 1, 0) -> 0 | F18: =IF(COUNTIF(Table4[Tag Number], A18), 1, 0) -> 0 | G18: =SUM(C18:F18) -> 0 | H18: {=_xlfn.IFS(OR(_xlfn.XLOOKUP(A18,Table1[Tag Number],Table1[Status],"-",0)="Dead", _xlfn.XLOOKUP(A18,Table2[Tag Number],Table2[Status],"-",0)="Dead", _xlfn.XLOOKUP(A18,Table3[Tag Number],Table3[Status],"-",0)="Dead", _xlfn.XLOOKUP(A18,Table4[Tag Number],Table4[Status],"-",0)="Dead"),"Dead", OR(_xlfn.XLOOKUP(A18,Table1[Tag Number],Table1[Status],"-",0)="Alive", _xlfn.XLOOKUP(A18,Table2[Tag Number],Table2[Status],"-",0)="Alive", _xlfn.XLOOKUP(A18,Table3[Tag Number],Table3[Status],"-",0)="Alive", _xlfn.XLOOKUP(A18,Table4[Tag Number],Table4[Status],"-",0)="Alive"),"Alive", OR(_xlfn.XLOOKUP(A18,Table1[Tag Number],Table1[Status],"-",0)="-", _xlfn.XLOOKUP(A18,Table2[Tag Number],Table2[Status],"-",0)="-", _xlfn.XLOOKUP(A18,Table3[Tag Number],Table3[Status],"-",0)="-", _xlfn.XLOOKUP(A18,Table4[Tag Number],Table4[Status],"-",0)="-"), "-")} -> - | J18: Retagged Dead | K18: {=SUM(COUNTIFS(Table1[Tag Number],{"*O*"},Table1[Status],"Dead"))} -> 0 | L18: {=SUM(COUNTIFS(Table2[Tag Number],{"O*"},Table2[Status],"Dead"))} -> 0 | M18: {=SUM(COUNTIFS(Table3[Tag Number],{"O*"},Table3[Status],"Dead"))} -> 0 | N18: {=SUM(COUNTIFS(Table4[Tag Number],{"O*"},Table4[Status],"Dead"))} -> 0 | R18: =IF(G18>1,A18) -> FALSE
A19: B015 | B19: Glade | C19: =IF(COUNTIF(Table1[Tag Number], A19), 1, 0) -> 0 | D19: =IF(COUNTIF(Table2[Tag Number], A19), 1, 0) -> 0 | E19: =IF(COUNTIF(Table3[Tag Number], A19), 1, 0) -> 0 | F19: =IF(COUNTIF(Table4[Tag Number], A19), 1, 0) -> 0 | G19: =SUM(C19:F19) -> 0 | H19: {=_xlfn.IFS(OR(_xlfn.XLOOKUP(A19,Table1[Tag Number],Table1[Status],"-",0)="Dead", _xlfn.XLOOKUP(A19,Table2[Tag Number],Table2[Status],"-",0)="Dead", _xlfn.XLOOKUP(A19,Table3[Tag Number],Table3[Status],"-",0)="Dead", _xlfn.XLOOKUP(A19,Table4[Tag Number],Table4[Status],"-",0)="Dead"),"Dead", OR(_xlfn.XLOOKUP(A19,Table1[Tag Number],Table1[Status],"-",0)="Alive", _xlfn.XLOOKUP(A19,Table2[Tag Number],Table2[Status],"-",0)="Alive", _xlfn.XLOOKUP(A19,Table3[Tag Number],Table3[Status],"-",0)="Alive", _xlfn.XLOOKUP(A19,Table4[Tag Number],Table4[Status],"-",0)="Alive"),"Alive", OR(_xlfn.XLOOKUP(A19,Table1[Tag Number],Table1[Status],"-",0)="-", _xlfn.XLOOKUP(A19,Table2[Tag Number],Table2[Status],"-",0)="-", _xlfn.XLOOKUP(A19,Table3[Tag Number],Table3[Status],"-",0)="-", _xlfn.XLOOKUP(A19,Table4[Tag Number],Table4[Status],"-",0)="-"), "-")} -> - | J19: Sums: | K19: =SUM(K11:K18) -> 74 | L19: =SUM(L11:L18) -> 68 | M19: =SUM(M11:M18) -> 74 | N19: =SUM(N11:N18) -> 62 | R19: =IF(G19>1,A19) -> FALSE
A20: B016 | B20: Glade | C20: =IF(COUNTIF(Table1[Tag Number], A20), 1, 0) -> 0 | D20: =IF(COUNTIF(Table2[Tag Number], A20), 1, 0) -> 0 | E20: =IF(COUNTIF(Table3[Tag Number], A20), 1, 0) -> 0 | F20: =IF(COUNTIF(Table4[Tag Number], A20), 1, 0) -> 0 | G20: =SUM(C20:F20) -> 0 | H20: {=_xlfn.IFS(OR(_xlfn.XLOOKUP(A20,Table1[Tag Number],Table1[Status],"-",0)="Dead", _xlfn.XLOOKUP(A20,Table2[Tag Number],Table2[Status],"-",0)="Dead", _xlfn.XLOOKUP(A20,Table3[Tag Number],Table3[Status],"-",0)="Dead", _xlfn.XLOOKUP(A20,Table4[Tag Number],Table4[Status],"-",0)="Dead"),"Dead", OR(_xlfn.XLOOKUP(A20,Table1[Tag Number],Table1[Status],"-",0)="Alive", _xlfn.XLOOKUP(A20,Table2[Tag Number],Table2[Status],"-",0)="Alive", _xlfn.XLOOKUP(A20,Table3[Tag Number],Table3[Status],"-",0)="Alive", _xlfn.XLOOKUP(A20,Table4[Tag Number],Table4[Status],"-",0)="Alive"),"Alive", OR(_xlfn.XLOOKUP(A20,Table1[Tag Number],Table1[Status],"-",0)="-", _xlfn.XLOOKUP(A20,Table2[Tag Number],Table2[Status],"-",0)="-", _xlfn.XLOOKUP(A20,Table3[Tag Number],Table3[Status],"-",0)="-", _xlfn.XLOOKUP(A20,Table4[Tag Number],Table4[Status],"-",0)="-"), "-")} -> - | J20: All deads: | K20: =SUM(K15:N18) -> 144 | R20: =IF(G20>1,A20) -> FALSE
A21: B017 | B21: Glade | C21: =IF(COUNTIF(Table1[Tag Number], A21), 1, 0) -> 0 | D21: =IF(COUNTIF(Table2[Tag Number], A21), 1, 0) -> 0 | E21: =IF(COUNTIF(Table3[Tag Number], A21), 1, 0) -> 0 | F21: =IF(COUNTIF(Table4[Tag Number], A21), 1, 0) -> 0 | G21: =SUM(C21:F21) -> 0 | H21: {=_xlfn.IFS(OR(_xlfn.XLOOKUP(A21,Table1[Tag Number],Table1[Status],"-",0)="Dead", _xlfn.XLOOKUP(A21,Table2[Tag Number],Table2[Status],"-",0)="Dead", _xlfn.XLOOKUP(A21,Table3[Tag Number],Table3[Status],"-",0)="Dead", _xlfn.XLOOKUP(A21,Table4[Tag Number],Table4[Status],"-",0)="Dead"),"Dead", OR(_xlfn.XLOOKUP(A21,Table1[Tag Number],Table1[Status],"-",0)="Alive", _xlfn.XLOOKUP(A21,Table2[Tag Number],Table2[Status],"-",0)="Alive", _xlfn.XLOOKUP(A21,Table3[Tag Number],Table3[Status],"-",0)="Alive", _xlfn.XLOOKUP(A21,Table4[Tag Number],Table4[Status],"-",0)="Alive"),"Alive", OR(_xlfn.XLOOKUP(A21,Table1[Tag Number],Table1[Status],"-",0)="-", _xlfn.XLOOKUP(A21,Table2[Tag Number],Table2[Status],"-",0)="-", _xlfn.XLOOKUP(A21,Table3[Tag Number],Table3[Status],"-",0)="-", _xlfn.XLOOKUP(A21,Table4[Tag Number],Table4[Status],"-",0)="-"), "-")} -> - | R21: =IF(G21>1,A21) -> FALSE
A22: B018 | B22: Glade | C22: =IF(COUNTIF(Table1[Tag Number], A22), 1, 0) -> 0 | D22: =IF(COUNTIF(Table2[Tag Number], A22), 1, 0) -> 0 | E22: =IF(COUNTIF(Table3[Tag Number], A22), 1, 0) -> 0 | F22: =IF(COUNTIF(Table4[Tag Number], A22), 1, 0) -> 0 | G22: =SUM(C22:F22) -> 0 | H22: {=_xlfn.IFS(OR(_xlfn.XLOOKUP(A22,Table1[Tag Number],Table1[Status],"-",0)="Dead", _xlfn.XLOOKUP(A22,Table2[Tag Number],Table2[Status],"-",0)="Dead", _xlfn.XLOOKUP(A22,Table3[Tag Number],Table3[Status],"-",0)="Dead", _xlfn.XLOOKUP(A22,Table4[Tag Number],Table4[Status],"-",0)="Dead"),"Dead", OR(_xlfn.XLOOKUP(A22,Table1[Tag Number],Table1[Status],"-",0)="Alive", _xlfn.XLOOKUP(A22,Table2[Tag Number],Table2[Status],"-",0)="Alive", _xlfn.XLOOKUP(A22,Table3[Tag Number],Table3[Status],"-",0)="Alive", _xlfn.XLOOKUP(A22,Table4[Tag Number],Table4[Status],"-",0)="Alive"),"Alive", OR(_xlfn.XLOOKUP(A22,Table1[Tag Number],Table1[Status],"-",0)="-", _xlfn.XLOOKUP(A22,Table2[Tag Number],Table2[Status],"-",0)="-", _xlfn.XLOOKUP(A22,Table3[Tag Number],Table3[Status],"-",0)="-", _xlfn.XLOOKUP(A22,Table4[Tag Number],Table4[Status],"-",0)="-"), "-")} -> - | J22: Unknown Alive | K22: =SUM(K12:N12) -> 10 | R22: =IF(G22>1,A22) -> FALSE
A23: B019 | B23: Glade | C23: =IF(COUNTIF(Table1[Tag Number], A23), 1, 0) -> 0 | D23: =IF(COUNTIF(Table2[Tag Number], A23), 1, 0) -> 0 | E23: =IF(COUNTIF(Table3[Tag Number], A23), 1, 0) -> 0 | F23: =IF(COUNTIF(Table4[Tag Number], A23), 1, 0) -> 0 | G23: =SUM(C23:F23) -> 0 | H23: {=_xlfn.IFS(OR(_xlfn.XLOOKUP(A23,Table1[Tag Number],Table1[Status],"-",0)="Dead", _xlfn.XLOOKUP(A23,Table2[Tag Number],Table2[Status],"-",0)="Dead", _xlfn.XLOOKUP(A23,Table3[Tag Number],Table3[Status],"-",0)="Dead", _xlfn.XLOOKUP(A23,Table4[Tag Number],Table4[Status],"-",0)="Dead"),"Dead", OR(_xlfn.XLOOKUP(A23,Table1[Tag Number],Table1[Status],"-",0)="Alive", _xlfn.XLOOKUP(A23,Table2[Tag Number],Table2[Status],"-",0)="Alive", _xlfn.XLOOKUP(A23,Table3[Tag Number],Table3[Status],"-",0)="Alive", _xlfn.XLOOKUP(A23,Table4[Tag Number],Table4[Status],"-",0)="Alive"),"Alive", OR(_xlfn.XLOOKUP(A23,Table1[Tag Number],Table1[Status],"-",0)="-", _xlfn.XLOOKUP(A23,Table2[Tag Number],Table2[Status],"-",0)="-", _xlfn.XLOOKUP(A23,Table3[Tag Number],Table3[Status],"-",0)="-", _xlfn.XLOOKUP(A23,Table4[Tag Number],Table4[Status],"-",0)="-"), "-")} -> - | R23: =IF(G23>1,A23) -> FALSE
A24: B020 | B24: Snakeden | C24: =IF(COUNTIF(Table1[Tag Number], A24), 1, 0) -> 0 | D24: =IF(COUNTIF(Table2[Tag Number], A24), 1, 0) -> 0 | E24: =IF(COUNTIF(Table3[Tag Number], A24), 1, 0) -> 0 | F24: =IF(COUNTIF(Table4[Tag Number], A24), 1, 0) -> 0 | G24: =SUM(C24:F24) -> 0 | H24: {=_xlfn.IFS(OR(_xlfn.XLOOKUP(A24,Table1[Tag Number],Table1[Status],"-",0)="Dead", _xlfn.XLOOKUP(A24,Table2[Tag Number],Table2[Status],"-",0)="Dead", _xlfn.XLOOKUP(A24,Table3[Tag Number],Table3[Status],"-",0)="Dead", _xlfn.XLOOKUP(A24,Table4[Tag Number],Table4[Status],"-",0)="Dead"),"Dead", OR(_xlfn.XLOOKUP(A24,Table1[Tag Number],Table1[Status],"-",0)="Alive", _xlfn.XLOOKUP(A24,Table2[Tag Number],Table2[Status],"-",0)="Alive", _xlfn.XLOOKUP(A24,Table3[Tag Number],Table3[Status],"-",0)="Alive", _xlfn.XLOOKUP(A24,Table4[Tag Number],Table4[Status],"-",0)="Alive"),"Alive", OR(_xlfn.XLOOKUP(A24,Table1[Tag Number],Table1[Status],"-",0)="-", _xlfn.XLOOKUP(A24,Table2[Tag Number],Table2[Status],"-",0)="-", _xlfn.XLOOKUP(A24,Table3[Tag Number],Table3[Status],"-",0)="-", _xlfn.XLOOKUP(A24,Table4[Tag Number],Table4[Status],"-",0)="-"), "-")} -> - | R24: =IF(G24>1,A24) -> FALSE
A25: B021 | B25: Snakeden | C25: =IF(COUNTIF(Table1[Tag Number], A25), 1, 0) -> 0 | D25: =IF(COUNTIF(Table2[Tag Number], A25), 1, 0) -> 0 | E25: =IF(COUNTIF(Table3[Tag Number], A25), 1, 0) -> 0 | F25: =IF(COUNTIF(Table4[Tag Number], A25), 1, 0) -> 0 | G25: =SUM(C25:F25) -> 0 | H25: {=_xlfn.IFS(OR(_xlfn.XLOOKUP(A25,Table1[Tag Number],Table1[Status],"-",0)="Dead", _xlfn.XLOOKUP(A25,Table2[Tag Number],Table2[Status],"-",0)="Dead", _xlfn.XLOOKUP(A25,Table3[Tag Number],Table3[Status],"-",0)="Dead", _xlfn.XLOOKUP(A25,Table4[Tag Number],Table4[Status],"-",0)="Dead"),"Dead", OR(_xlfn.XLOOKUP(A25,Table1[Tag Number],Table1[Status],"-",0)="Alive", _xlfn.XLOOKUP(A25,Table2[Tag Number],Table2[Status],"-",0)="Alive", _xlfn.XLOOKUP(A25,Table3[Tag Number],Table3[Status],"-",0)="Alive", _xlfn.XLOOKUP(A25,Table4[Tag Number],Table4[Status],"-",0)="Alive"),"Alive", OR(_xlfn.XLOOKUP(A25,Table1[Tag Number],Table1[Status],"-",0)="-", _xlfn.XLOOKUP(A25,Table2[Tag Number],Table2[Status],"-",0)="-", _xlfn.XLOOKUP(A25,Table3[Tag Number],Table3[Status],"-",0)="-", _xlfn.XLOOKUP(A25,Table4[Tag Number],Table4[Status],"-",0)="-"), "-")} -> - | J25: Includes Retagged | M25: Does Not Include Retagged | R25: =IF(G25>1,A25) -> FALSE
A26: B022 | B26: Glade | C26: =IF(COUNTIF(Table1[Tag Number], A26), 1, 0) -> 0 | D26: =IF(COUNTIF(Table2[Tag Number], A26), 1, 0) -> 0 | E26: =IF(COUNTIF(Table3[Tag Number], A26), 1, 0) -> 0 | F26: =IF(COUNTIF(Table4[Tag Number], A26), 1, 0) -> 0 | G26: =SUM(C26:F26) -> 0 | H26: {=_xlfn.IFS(OR(_xlfn.XLOOKUP(A26,Table1[Tag Number],Table1[Status],"-",0)="Dead", _xlfn.XLOOKUP(A26,Table2[Tag Number],Table2[Status],"-",0)="Dead", _xlfn.XLOOKUP(A26,Table3[Tag Number],Table3[Status],"-",0)="Dead", _xlfn.XLOOKUP(A26,Table4[Tag Number],Table4[Status],"-",0)="Dead"),"Dead", OR(_xlfn.XLOOKUP(A26,Table1[Tag Number],Table1[Status],"-",0)="Alive", _xlfn.XLOOKUP(A26,Table2[Tag Number],Table2[Status],"-",0)="Alive", _xlfn.XLOOKUP(A26,Table3[Tag Number],Table3[Status],"-",0)="Alive", _xlfn.XLOOKUP(A26,Table4[Tag Number],Table4[Status],"-",0)="Alive"),"Alive", OR(_xlfn.XLOOKUP(A26,Table1[Tag Number],Table1[Status],"-",0)="-", _xlfn.XLOOKUP(A26,Table2[Tag Number],Table2[Status],"-",0)="-", _xlfn.XLOOKUP(A26,Table3[Tag Number],Table3[Status],"-",0)="-", _xlfn.XLOOKUP(A26,Table4[Tag Number],Table4[Status],"-",0)="-"), "-")} -> - | J26: Tagged Mussels Found (At least once) | K26: =SUM(K29:K32) -> 213 | M26: Tagged Mussels Found (At least once) | N26: =SUM(N29:N32) -> 203 | R26: =IF(G26>1,A26) -> FALSE
A27: B023 | B27: Glade | C27: =IF(COUNTIF(Table1[Tag Number], A27), 1, 0) -> 0 | D27: =IF(COUNTIF(Table2[Tag Number], A27), 1, 0) -> 0 | E27: =IF(COUNTIF(Table3[Tag Number], A27), 1, 0) -> 0 | F27: =IF(COUNTIF(Table4[Tag Number], A27), 1, 0) -> 0 | G27: =SUM(C27:F27) -> 0 | H27: {=_xlfn.IFS(OR(_xlfn.XLOOKUP(A27,Table1[Tag Number],Table1[Status],"-",0)="Dead", _xlfn.XLOOKUP(A27,Table2[Tag Number],Table2[Status],"-",0)="Dead", _xlfn.XLOOKUP(A27,Table3[Tag Number],Table3[Status],"-",0)="Dead", _xlfn.XLOOKUP(A27,Table4[Tag Number],Table4[Status],"-",0)="Dead"),"Dead", OR(_xlfn.XLOOKUP(A27,Table1[Tag Number],Table1[Status],"-",0)="Alive", _xlfn.XLOOKUP(A27,Table2[Tag Number],Table2[Status],"-",0)="Alive", _xlfn.XLOOKUP(A27,Table3[Tag Number],Table3[Status],"-",0)="Alive", _xlfn.XLOOKUP(A27,Table4[Tag Number],Table4[Status],"-",0)="Alive"),"Alive", OR(_xlfn.XLOOKUP(A27,Table1[Tag Number],Table1[Status],"-",0)="-", _xlfn.XLOOKUP(A27,Table2[Tag Number],Table2[Status],"-",0)="-", _xlfn.XLOOKUP(A27,Table3[Tag Number],Table3[Status],"-",0)="-", _xlfn.XLOOKUP(A27,Table4[Tag Number],Table4[Status],"-",0)="-"), "-")} -> - | J27: Total Observations | K27: =SUM(K8:N8) -> 278 | R27: =IF(G27>1,A27) -> FALSE
A28: B024 | B28: Snakeden | C28: =IF(COUNTIF(Table1[Tag Number], A28), 1, 0) -> 0 | D28: =IF(COUNTIF(Table2[Tag Number], A28), 1, 0) -> 0 | E28: =IF(COUNTIF(Table3[Tag Number], A28), 1, 0) -> 0 | F28: =IF(COUNTIF(Table4[Tag Number], A28), 1, 0) -> 0 | G28: =SUM(C28:F28) -> 0 | H28: {=_xlfn.IFS(OR(_xlfn.XLOOKUP(A28,Table1[Tag Number],Table1[Status],"-",0)="Dead", _xlfn.XLOOKUP(A28,Table2[Tag Number],Table2[Status],"-",0)="Dead", _xlfn.XLOOKUP(A28,Table3[Tag Number],Table3[Status],"-",0)="Dead", _xlfn.XLOOKUP(A28,Table4[Tag Number],Table4[Status],"-",0)="Dead"),"Dead", OR(_xlfn.XLOOKUP(A28,Table1[Tag Number],Table1[Status],"-",0)="Alive", _xlfn.XLOOKUP(A28,Table2[Tag Number],Table2[Status],"-",0)="Alive", _xlfn.XLOOKUP(A28,Table3[Tag Number],Table3[Status],"-",0)="Alive", _xlfn.XLOOKUP(A28,Table4[Tag Number],Table4[Status],"-",0)="Alive"),"Alive", OR(_xlfn.XLOOKUP(A28,Table1[Tag Number],Table1[Status],"-",0)="-", _xlfn.XLOOKUP(A28,Table2[Tag Number],Table2[Status],"-",0)="-", _xlfn.XLOOKUP(A28,Table3[Tag Number],Table3[Status],"-",0)="-", _xlfn.XLOOKUP(A28,Table4[Tag Number],Table4[Status],"-",0)="-"), "-")} -> - | J28: Found in multiple passes | K28: =COUNTIF(G4:G2998,">1") -> 25 | M28: Found in multiple passes | N28: =COUNTIF(G4:G2805,">1") -> 23 | R28: =IF(G28>1,A28) -> FALSE
A29: B025 | B29: Glade | C29: =IF(COUNTIF(Table1[Tag Number], A29), 1, 0) -> 0 | D29: =IF(COUNTIF(Table2[Tag Number], A29), 1, 0) -> 0 | E29: =IF(COUNTIF(Table3[Tag Number], A29), 1, 0) -> 0 | F29: =IF(COUNTIF(Table4[Tag Number], A29), 1, 0) -> 0 | G29: =SUM(C29:F29) -> 0 | H29: {=_xlfn.IFS(OR(_xlfn.XLOOKUP(A29,Table1[Tag Number],Table1[Status],"-",0)="Dead", _xlfn.XLOOKUP(A29,Table2[Tag Number],Table2[Status],"-",0)="Dead", _xlfn.XLOOKUP(A29,Table3[Tag Number],Table3[Status],"-",0)="Dead", _xlfn.XLOOKUP(A29,Table4[Tag Number],Table4[Status],"-",0)="Dead"),"Dead", OR(_xlfn.XLOOKUP(A29,Table1[Tag Number],Table1[Status],"-",0)="Alive", _xlfn.XLOOKUP(A29,Table2[Tag Number],Table2[Status],"-",0)="Alive", _xlfn.XLOOKUP(A29,Table3[Tag Number],Table3[Status],"-",0)="Alive", _xlfn.XLOOKUP(A29,Table4[Tag Number],Table4[Status],"-",0)="Alive"),"Alive", OR(_xlfn.XLOOKUP(A29,Table1[Tag Number],Table1[Status],"-",0)="-", _xlfn.XLOOKUP(A29,Table2[Tag Number],Table2[Status],"-",0)="-", _xlfn.XLOOKUP(A29,Table3[Tag Number],Table3[Status],"-",0)="-", _xlfn.XLOOKUP(A29,Table4[Tag Number],Table4[Status],"-",0)="-"), "-")} -> - | J29: Tagged Mussels Found only Once | K29: =COUNTIF(G4:G2998,"1") -> 188 | M29: Tagged Mussels Found only Once | N29: =COUNTIF(G4:G2805,"1") -> 180 | R29: =IF(G29>1,A29) -> FALSE
